Workbook

Sheet Leia-me
A1: T2 – Rede de filas de uma assistência técnica (modelo hipotético)
A2: Integrantes: Artur Lemos Pereira, Raul Neves Pedroso, Humberto Corrêa Gomes
A3: Fonte: T2/resultados/inicial.json e melhorado.json; abas Estados_* e Indices usam a semente 42.
A4: Premissas: cliente = ordem de serviço; FIFO; K inclui quem está em serviço; chegada a fila cheia = perda.
A5: Unidades: tempos em minutos; D em atendimentos/min e D_h = 60*D em atendimentos/h; W em min/visita; perdas_h em perdas/h.
A6: Notação do M9 (Prof. Afonso Sales, PUCRS 2026/2), i = 1..K: pi_i = tempo_i / T (coluna p_n); N = SUM(pi_i*i); mu = 1/E[S], E[S] = (a+b)/2; mu_i = MIN(i,c)*mu; D = SUM(pi_i*mu_i) = mu*B; U = SUM(pi_i*MIN(i,c)/c) = B/c; W = N/D.
A7: B = SUM(MIN(n,c)*p_n) é auxiliar (servidores ocupados); o estado 0 contribui 0. perdas_h = 60*perdas/T.
A8: Dicionário com o JSON/CSV (chaves inalteradas): N = L, D = X, D_h = X_h, W = R; U, B, perdas, perdas_h iguais.
A9: Fórmulas conferidas com as imagens do M9 fornecidas pelo grupo.
A10: D é estimativa da vazão local pela ocupação (inclui revisitas Q3→Q2), não contagem; W é estimativa de longo prazo por visita.
A11: P(K) não é a probabilidade de perda (chegadas não Poisson).
A12: Replicacoes: valores exportados do JSON; resumo (média/mín/máx) por fórmulas, descritivo, sem IC.

Sheet Estados_inicial
A1: Cenário | B1: inicial
A2: T (min) | B2: 1411699.2
A3: Semente | B3: 42
A5: Fila | B5: c | C5: a (min) | D5: b (min) | E5: Perdas | F5: n | G5: Tempo_n (min) | H5: p_n | I5: n*p_n | J5: min(n,c)*p_n
A6: Q1 | B6: 1 | C6: 2 | D6: 4 | E6: 0 | F6: 0 | G6: 705259.35 | H6: =G6/$B$2 -> 0.49958189 | I6: =F6*H6 -> 0 | J6: =MIN(F6,B6)*H6 -> 0
A7: Q1 | B7: 1 | C7: 2 | D7: 4 | E7: 0 | F7: 1 | G7: 706439.84 | H7: =G7/$B$2 -> 0.50041811 | I7: =F7*H7 -> 0.50041811 | J7: =MIN(F7,B7)*H7 -> 0.50041811
A8: Q1 | B8: 1 | C8: 2 | D8: 4 | E8: 0 | F8: 2 | G8: 0 | H8: =G8/$B$2 -> 0 | I8: =F8*H8 -> 0 | J8: =MIN(F8,B8)*H8 -> 0
A9: Q1 | B9: 1 | C9: 2 | D9: 4 | E9: 0 | F9: 3 | G9: 0 | H9: =G9/$B$2 -> 0 | I9: =F9*H9 -> 0 | J9: =MIN(F9,B9)*H9 -> 0
A10: Q1 | B10: 1 | C10: 2 | D10: 4 | E10: 0 | F10: 4 | G10: 0 | H10: =G10/$B$2 -> 0 | I10: =F10*H10 -> 0 | J10: =MIN(F10,B10)*H10 -> 0
A11: Q1 | B11: 1 | C11: 2 | D11: 4 | E11: 0 | F11: 5 | G11: 0 | H11: =G11/$B$2 -> 0 | I11: =F11*H11 -> 0 | J11: =MIN(F11,B11)*H11 -> 0
A12: Q2 | B12: 1 | C12: 6 | D12: 10 | E12: 94045 | F12: 0 | G12: 9.2788536 | H12: =G12/$B$2 -> 6.5728263e-06 | I12: =F12*H12 -> 0 | J12: =MIN(F12,B12)*H12 -> 0
A13: Q2 | B13: 1 | C13: 6 | D13: 10 | E13: 94045 | F13: 1 | G13: 7.5354601 | H13: =G13/$B$2 -> 5.3378653e-06 | I13: =F13*H13 -> 5.3378653e-06 | J13: =MIN(F13,B13)*H13 -> 5.3378653e-06
A14: Q2 | B14: 1 | C14: 6 | D14: 10 | E14: 94045 | F14: 2 | G14: 2.9180561 | H14: =G14/$B$2 -> 2.0670523e-06 | I14: =F14*H14 -> 4.1341047e-06 | J14: =MIN(F14,B14)*H14 -> 2.0670523e-06
A15: Q2 | B15: 1 | C15: 6 | D15: 10 | E15: 94045 | F15: 3 | G15: 18.80956 | H15: =G15/$B$2 -> 1.3324057e-05 | I15: =F15*H15 -> 3.997217e-05 | J15: =MIN(F15,B15)*H15 -> 1.3324057e-05
A16: Q2 | B16: 1 | C16: 6 | D16: 10 | E16: 94045 | F16: 4 | G16: 7.3532577 | H16: =G16/$B$2 -> 5.2087992e-06 | I16: =F16*H16 -> 2.0835197e-05 | J16: =MIN(F16,B16)*H16 -> 5.2087992e-06
A17: Q2 | B17: 1 | C17: 6 | D17: 10 | E17: 94045 | F17: 5 | G17: 20.664983 | H17: =G17/$B$2 -> 1.4638375e-05 | I17: =F17*H17 -> 7.3191877e-05 | J17: =MIN(F17,B17)*H17 -> 1.4638375e-05
... A26: Q3 | B26: 1 | C26: 2 | D26: 4 | E26: 0 | F26: 5 | G26: 0 | H26: =G26/$B$2 -> 0 | I26: =F26*H26 -> 0 | J26: =MIN(F26,B26)*H26 -> 0

Sheet Estados_melhorado
A1: Cenário | B1: melhorado
A2: T (min) | B2: 1043673.9
A3: Semente | B3: 42
A5: Fila | B5: c | C5: a (min) | D5: b (min) | E5: Perdas | F5: n | G5: Tempo_n (min) | H5: p_n | I5: n*p_n | J5: min(n,c)*p_n
A6: Q1 | B6: 1 | C6: 2 | D6: 4 | E6: 0 | F6: 0 | G6: 521701.06 | H6: =G6/$B$2 -> 0.49986981 | I6: =F6*H6 -> 0 | J6: =MIN(F6,B6)*H6 -> 0
A7: Q1 | B7: 1 | C7: 2 | D7: 4 | E7: 0 | F7: 1 | G7: 521972.81 | H7: =G7/$B$2 -> 0.50013019 | I7: =F7*H7 -> 0.50013019 | J7: =MIN(F7,B7)*H7 -> 0.50013019
A8: Q1 | B8: 1 | C8: 2 | D8: 4 | E8: 0 | F8: 2 | G8: 0 | H8: =G8/$B$2 -> 0 | I8: =F8*H8 -> 0 | J8: =MIN(F8,B8)*H8 -> 0
A9: Q1 | B9: 1 | C9: 2 | D9: 4 | E9: 0 | F9: 3 | G9: 0 | H9: =G9/$B$2 -> 0 | I9: =F9*H9 -> 0 | J9: =MIN(F9,B9)*H9 -> 0
A10: Q1 | B10: 1 | C10: 2 | D10: 4 | E10: 0 | F10: 4 | G10: 0 | H10: =G10/$B$2 -> 0 | I10: =F10*H10 -> 0 | J10: =MIN(F10,B10)*H10 -> 0
A11: Q1 | B11: 1 | C11: 2 | D11: 4 | E11: 0 | F11: 5 | G11: 0 | H11: =G11/$B$2 -> 0 | I11: =F11*H11 -> 0 | J11: =MIN(F11,B11)*H11 -> 0
A12: Q2 | B12: 2 | C12: 6 | D12: 10 | E12: 12 | F12: 0 | G12: 4565.1106 | H12: =G12/$B$2 -> 0.0043740777 | I12: =F12*H12 -> 0 | J12: =MIN(F12,B12)*H12 -> 0
A13: Q2 | B13: 2 | C13: 6 | D13: 10 | E13: 12 | F13: 1 | G13: 339527.26 | H13: =G13/$B$2 -> 0.32531931 | I13: =F13*H13 -> 0.32531931 | J13: =MIN(F13,B13)*H13 -> 0.32531931
A14: Q2 | B14: 2 | C14: 6 | D14: 10 | E14: 12 | F14: 2 | G14: 425125.02 | H14: =G14/$B$2 -> 0.40733512 | I14: =F14*H14 -> 0.81467024 | J14: =MIN(F14,B14)*H14 -> 0.81467024
A15: Q2 | B15: 2 | C15: 6 | D15: 10 | E15: 12 | F15: 3 | G15: 192933.28 | H15: =G15/$B$2 -> 0.18485975 | I15: =F15*H15 -> 0.55457924 | J15: =MIN(F15,B15)*H15 -> 0.36971949
A16: Q2 | B16: 2 | C16: 6 | D16: 10 | E16: 12 | F16: 4 | G16: 57952.003 | H16: =G16/$B$2 -> 0.055526928 | I16: =F16*H16 -> 0.22210771 | J16: =MIN(F16,B16)*H16 -> 0.11105386
A17: Q2 | B17: 2 | C17: 6 | D17: 10 | E17: 12 | F17: 5 | G17: 17024.755 | H17: =G17/$B$2 -> 0.016312333 | I17: =F17*H17 -> 0.081561664 | J17: =MIN(F17,B17)*H17 -> 0.032624666
... A26: Q3 | B26: 1 | C26: 2 | D26: 4 | E26: 0 | F26: 5 | G26: 0 | H26: =G26/$B$2 -> 0 | I26: =F26*H26 -> 0 | J26: =MIN(F26,B26)*H26 -> 0

Sheet Indices
A1: Cenário | B1: Fila | C1: c | D1: T (min) | E1: a (min) | F1: b (min) | G1: Perdas | H1: Soma p_n | I1: N | J1: B | K1: U | L1: E[S] (min) | M1: mu (/min/servidor) | N1: D (/min) | O1: D_h (/h) | P1: W (min/visita) | Q1: Perdas_h (/h)
A2: inicial | B2: Q1 | C2: =Estados_inicial!B6 -> 1 | D2: =Estados_inicial!$B$2 -> 1411699.2 | E2: =Estados_inicial!C6 -> 2 | F2: =Estados_inicial!D6 -> 4 | G2: =Estados_inicial!E6 -> 0 | H2: =SUM(Estados_inicial!H6:H11) -> 1 | I2: =SUM(Estados_inicial!I6:I11) -> 0.50041811 | J2: =SUM(Estados_inicial!J6:J11) -> 0.50041811 | K2: =J2/C2 -> 0.50041811 | L2: =(E2+F2)/2 -> 3 | M2: =1/L2 -> 0.33333333 | N2: =M2*J2 -> 0.16680604 | O2: =60*N2 -> 10.008362 | P2: =IF(N2>0,I2/N2,"") -> 3 | Q2: =60*G2/D2 -> 0
A3: inicial | B3: Q2 | C3: =Estados_inicial!B12 -> 1 | D3: =Estados_inicial!$B$2 -> 1411699.2 | E3: =Estados_inicial!C12 -> 6 | F3: =Estados_inicial!D12 -> 10 | G3: =Estados_inicial!E12 -> 94045 | H3: =SUM(Estados_inicial!H12:H20) -> 1 | I3: =SUM(Estados_inicial!I12:I20) -> 7.6303994 | J3: =SUM(Estados_inicial!J12:J20) -> 0.99999343 | K3: =J3/C3 -> 0.99999343 | L3: =(E3+F3)/2 -> 8 | M3: =1/L3 -> 0.125 | N3: =M3*J3 -> 0.12499918 | O3: =60*N3 -> 7.4999507 | P3: =IF(N3>0,I3/N3,"") -> 61.043596 | Q3: =60*G3/D3 -> 3.997098
A4: inicial | B4: Q3 | C4: =Estados_inicial!B21 -> 1 | D4: =Estados_inicial!$B$2 -> 1411699.2 | E4: =Estados_inicial!C21 -> 2 | F4: =Estados_inicial!D21 -> 4 | G4: =Estados_inicial!E21 -> 0 | H4: =SUM(Estados_inicial!H21:H26) -> 1 | I4: =SUM(Estados_inicial!I21:I26) -> 0.37491862 | J4: =SUM(Estados_inicial!J21:J26) -> 0.37491862 | K4: =J4/C4 -> 0.37491862 | L4: =(E4+F4)/2 -> 3 | M4: =1/L4 -> 0.33333333 | N4: =M4*J4 -> 0.12497287 | O4: =60*N4 -> 7.4983724 | P4: =IF(N4>0,I4/N4,"") -> 3 | Q4: =60*G4/D4 -> 0
A5: melhorado | B5: Q1 | C5: =Estados_melhorado!B6 -> 1 | D5: =Estados_melhorado!$B$2 -> 1043673.9 | E5: =Estados_melhorado!C6 -> 2 | F5: =Estados_melhorado!D6 -> 4 | G5: =Estados_melhorado!E6 -> 0 | H5: =SUM(Estados_melhorado!H6:H11) -> 1 | I5: =SUM(Estados_melhorado!I6:I11) -> 0.50013019 | J5: =SUM(Estados_melhorado!J6:J11) -> 0.50013019 | K5: =J5/C5 -> 0.50013019 | L5: =(E5+F5)/2 -> 3 | M5: =1/L5 -> 0.33333333 | N5: =M5*J5 -> 0.16671006 | O5: =60*N5 -> 10.002604 | P5: =IF(N5>0,I5/N5,"") -> 3 | Q5: =60*G5/D5 -> 0
A6: melhorado | B6: Q2 | C6: =Estados_melhorado!B12 -> 2 | D6: =Estados_melhorado!$B$2 -> 1043673.9 | E6: =Estados_melhorado!C12 -> 6 | F6: =Estados_melhorado!D12 -> 10 | G6: =Estados_melhorado!E12 -> 12 | H6: =SUM(Estados_melhorado!H12:H20) -> 1 | I6: =SUM(Estados_melhorado!I12:I20) -> 2.0374687 | J6: =SUM(Estados_melhorado!J12:J20) -> 1.6659325 | K6: =J6/C6 -> 0.83296627 | L6: =(E6+F6)/2 -> 8 | M6: =1/L6 -> 0.125 | N6: =M6*J6 -> 0.20824157 | O6: =60*N6 -> 12.494494 | P6: =IF(N6>0,I6/N6,"") -> 9.7841593 | Q6: =60*G6/D6 -> 0.00068987068
A7: melhorado | B7: Q3 | C7: =Estados_melhorado!B21 -> 1 | D7: =Estados_melhorado!$B$2 -> 1043673.9 | E7: =Estados_melhorado!C21 -> 2 | F7: =Estados_melhorado!D21 -> 4 | G7: =Estados_melhorado!E21 -> 0 | H7: =SUM(Estados_melhorado!H21:H26) -> 1 | I7: =SUM(Estados_melhorado!I21:I26) -> 0.69414946 | J7: =SUM(Estados_melhorado!J21:J26) -> 0.62493176 | K7: =J7/C7 -> 0.62493176 | L7: =(E7+F7)/2 -> 3 | M7: =1/L7 -> 0.33333333 | N7: =M7*J7 -> 0.20831059 | O7: =60*N7 -> 12.498635 | P7: =IF(N7>0,I7/N7,"") -> 3.3322813 | Q7: =60*G7/D7 -> 0

Sheet Comparacao
A1: Fila | B1: Métrica | C1: Inicial | D1: Melhorado | E1: Variação | F1: Unidade da variação
A2: Q1 | B2: N | C2: =Indices!I2 -> 0.50041811 | D2: =Indices!I5 -> 0.50013019 | E2: =IF(C2=0,"",(D2-C2)/C2) -> -0.00057536135 | F2: % relativo ao inicial
A3: Q1 | B3: U | C3: =Indices!K2 -> 0.50041811 | D3: =Indices!K5 -> 0.50013019 | E3: =(D3-C3)*100 -> -0.028792124 | F3: pontos percentuais
A4: Q1 | B4: D_h (/h) | C4: =Indices!O2 -> 10.008362 | D4: =Indices!O5 -> 10.002604 | E4: =IF(C4=0,"",(D4-C4)/C4) -> -0.00057536135 | F4: % relativo ao inicial
A5: Q1 | B5: W (min/visita) | C5: =Indices!P2 -> 3 | D5: =Indices!P5 -> 3 | E5: =IF(C5=0,"",(D5-C5)/C5) -> 1.4802974e-16 | F5: % relativo ao inicial
A6: Q1 | B6: Perdas | C6: =Indices!G2 -> 0 | D6: =Indices!G5 -> 0 | E6: =IF(C6=0,"",(D6-C6)/C6) | F6: % relativo ao inicial
A7: Q1 | B7: Perdas_h (/h) | C7: =Indices!Q2 -> 0 | D7: =Indices!Q5 -> 0 | E7: =IF(C7=0,"",(D7-C7)/C7) | F7: % relativo ao inicial
A8: Q2 | B8: N | C8: =Indices!I3 -> 7.6303994 | D8: =Indices!I6 -> 2.0374687 | E8: =IF(C8=0,"",(D8-C8)/C8) -> -0.73298008 | F8: % relativo ao inicial
A9: Q2 | B9: U | C9: =Indices!K3 -> 0.99999343 | D9: =Indices!K6 -> 0.83296627 | E9: =(D9-C9)*100 -> -16.702716 | F9: pontos percentuais
A10: Q2 | B10: D_h (/h) | C10: =Indices!O3 -> 7.4999507 | D10: =Indices!O6 -> 12.494494 | E10: =IF(C10=0,"",(D10-C10)/C10) -> 0.66594348 | F10: % relativo ao inicial
A11: Q2 | B11: W (min/visita) | C11: =Indices!P3 -> 61.043596 | D11: =Indices!P6 -> 9.7841593 | E11: =IF(C11=0,"",(D11-C11)/C11) -> -0.8397185 | F11: % relativo ao inicial
A12: Q2 | B12: Perdas | C12: =Indices!G3 -> 94045 | D12: =Indices!G6 -> 12 | E12: =IF(C12=0,"",(D12-C12)/C12) -> -0.9998724 | F12: % relativo ao inicial
A13: Q2 | B13: Perdas_h (/h) | C13: =Indices!Q3 -> 3.997098 | D13: =Indices!Q6 -> 0.00068987068 | E13: =IF(C13=0,"",(D13-C13)/C13) -> -0.99982741 | F13: % relativo ao inicial
A14: Q3 | B14: N | C14: =Indices!I4 -> 0.37491862 | D14: =Indices!I7 -> 0.69414946 | E14: =IF(C14=0,"",(D14-C14)/C14) -> 0.85146703 | F14: % relativo ao inicial
A15: Q3 | B15: U | C15: =Indices!K4 -> 0.37491862 | D15: =Indices!K7 -> 0.62493176 | E15: =(D15-C15)*100 -> 25.001314 | F15: pontos percentuais
A16: Q3 | B16: D_h (/h) | C16: =Indices!O4 -> 7.4983724 | D16: =Indices!O7 -> 12.498635 | E16: =IF(C16=0,"",(D16-C16)/C16) -> 0.66684642 | F16: % relativo ao inicial
A17: Q3 | B17: W (min/visita) | C17: =Indices!P4 -> 3 | D17: =Indices!P7 -> 3.3322813 | E17: =IF(C17=0,"",(D17-C17)/C17) -> 0.11076042 | F17: % relativo ao inicial
A18: Q3 | B18: Perdas | C18: =Indices!G4 -> 0 | D18: =Indices!G7 -> 0 | E18: =IF(C18=0,"",(D18-C18)/C18) | F18: % relativo ao inicial
A19: Q3 | B19: Perdas_h (/h) | C19: =Indices!Q4 -> 0 | D19: =Indices!Q7 -> 0 | E19: =IF(C19=0,"",(D19-C19)/C19) | F19: % relativo ao inicial

Sheet Replicacoes
A1: Cenário | B1: Semente | C1: Fila | D1: T (min) | E1: N | F1: B | G1: U | H1: D_h | I1: W | J1: perdas | K1: perdas_h
A2: inicial | B2: 42 | C2: Q1 | D2: 1411699.2 | E2: 0.50041811 | F2: 0.50041811 | G2: 0.50041811 | H2: 10.008362 | I2: 3 | J2: 0 | K2: 0
A3: inicial | B3: 43 | C3: Q1 | D3: 1412235.4 | E3: 0.49993056 | F3: 0.49993056 | G3: 0.49993056 | H3: 9.9986113 | I3: 3 | J3: 0 | K3: 0
A4: inicial | B4: 44 | C4: Q1 | D4: 1411950.8 | E4: 0.50069691 | F4: 0.50069691 | G4: 0.50069691 | H4: 10.013938 | I4: 3 | J4: 0 | K4: 0
A5: inicial | B5: 45 | C5: Q1 | D5: 1411681.1 | E5: 0.49992355 | F5: 0.49992355 | G5: 0.49992355 | H5: 9.9984709 | I5: 3 | J5: 0 | K5: 0
A6: inicial | B6: 46 | C6: Q1 | D6: 1411815.8 | E6: 0.49998425 | F6: 0.49998425 | G6: 0.49998425 | H6: 9.999685 | I6: 3 | J6: 0 | K6: 0
A7: inicial | B7: 47 | C7: Q1 | D7: 1412032.1 | E7: 0.49988987 | F7: 0.49988987 | G7: 0.49988987 | H7: 9.9977974 | I7: 3 | J7: 0 | K7: 0
A8: inicial | B8: 48 | C8: Q1 | D8: 1411959.3 | E8: 0.50002661 | F8: 0.50002661 | G8: 0.50002661 | H8: 10.000532 | I8: 3 | J8: 0 | K8: 0
A9: inicial | B9: 49 | C9: Q1 | D9: 1411882.4 | E9: 0.49991619 | F9: 0.49991619 | G9: 0.49991619 | H9: 9.9983237 | I9: 3 | J9: 0 | K9: 0
A10: inicial | B10: 50 | C10: Q1 | D10: 1411926.7 | E10: 0.4997633 | F10: 0.4997633 | G10: 0.4997633 | H10: 9.995266 | I10: 3 | J10: 0 | K10: 0
A11: inicial | B11: 51 | C11: Q1 | D11: 1411854.5 | E11: 0.49988924 | F11: 0.49988924 | G11: 0.49988924 | H11: 9.9977847 | I11: 3 | J11: 0 | K11: 0
A12: inicial | B12: 42 | C12: Q2 | D12: 1411699.2 | E12: 7.6303994 | F12: 0.99999343 | G12: 0.99999343 | H12: 7.4999507 | I12: 61.043596 | J12: 94045 | K12: 3.997098
A13: inicial | B13: 43 | C13: Q2 | D13: 1412235.4 | E13: 7.6300525 | F13: 0.99999381 | G13: 0.99999381 | H13: 7.4999536 | I13: 61.040798 | J13: 94136 | K13: 3.9994465
... A61: melhorado | B61: 51 | C61: Q3 | D61: 1044006.3 | E61: 0.69452885 | F61: 0.6246374 | G61: 0.6246374 | H61: 12.492748 | I61: 3.3356737 | J61: 0 | K61: 0
A63: Resumo por fórmulas (descritivo, sem intervalo de confiança)
A64: Cenário | B64: Fila | C64: Métrica | D64: Média | E64: Mín | F64: Máx | G64: n
A65: inicial | B65: Q1 | C65: N | D65: =AVERAGE(E2:E11) -> 0.50004386 | E65: =MIN(E2:E11) -> 0.4997633 | F65: =MAX(E2:E11) -> 0.50069691 | G65: =COUNT(E2:E11) -> 10
A66: inicial | B66: Q1 | C66: B | D66: =AVERAGE(F2:F11) -> 0.50004386 | E66: =MIN(F2:F11) -> 0.4997633 | F66: =MAX(F2:F11) -> 0.50069691 | G66: =COUNT(F2:F11) -> 10
A67: inicial | B67: Q1 | C67: U | D67: =AVERAGE(G2:G11) -> 0.50004386 | E67: =MIN(G2:G11) -> 0.4997633 | F67: =MAX(G2:G11) -> 0.50069691 | G67: =COUNT(G2:G11) -> 10
A68: inicial | B68: Q1 | C68: D_h | D68: =AVERAGE(H2:H11) -> 10.000877 | E68: =MIN(H2:H11) -> 9.995266 | F68: =MAX(H2:H11) -> 10.013938 | G68: =COUNT(H2:H11) -> 10
A69: inicial | B69: Q1 | C69: W | D69: =AVERAGE(I2:I11) -> 3 | E69: =MIN(I2:I11) -> 3 | F69: =MAX(I2:I11) -> 3 | G69: =COUNT(I2:I11) -> 10
A70: inicial | B70: Q1 | C70: perdas | D70: =AVERAGE(J2:J11) -> 0 | E70: =MIN(J2:J11) -> 0 | F70: =MAX(J2:J11) -> 0 | G70: =COUNT(J2:J11) -> 10
A71: inicial | B71: Q1 | C71: perdas_h | D71: =AVERAGE(K2:K11) -> 0 | E71: =MIN(K2:K11) -> 0 | F71: =MAX(K2:K11) -> 0 | G71: =COUNT(K2:K11) -> 10
A72: inicial | B72: Q2 | C72: N | D72: =AVERAGE(E12:E21) -> 7.6303205 | E72: =MIN(E12:E21) -> 7.6299382 | F72: =MAX(E12:E21) -> 7.6310025 | G72: =COUNT(E12:E21) -> 10
A73: inicial | B73: Q2 | C73: B | D73: =AVERAGE(F12:F21) -> 0.99999364 | E73: =MIN(F12:F21) -> 0.99999308 | F73: =MAX(F12:F21) -> 0.99999395 | G73: =COUNT(F12:F21) -> 10
A74: inicial | B74: Q2 | C74: U | D74: =AVERAGE(G12:G21) -> 0.99999364 | E74: =MIN(G12:G21) -> 0.99999308 | F74: =MAX(G12:G21) -> 0.99999395 | G74: =COUNT(G12:G21) -> 10
A75: inicial | B75: Q2 | C75: D_h | D75: =AVERAGE(H12:H21) -> 7.4999523 | E75: =MIN(H12:H21) -> 7.4999481 | F75: =MAX(H12:H21) -> 7.4999546 | G75: =COUNT(H12:H21) -> 10
A76: inicial | B76: Q2 | C76: W | D76: =AVERAGE(I12:I21) -> 61.042952 | E76: =MIN(I12:I21) -> 61.039895 | F76: =MAX(I12:I21) -> 61.048409 | G76: =COUNT(I12:I21) -> 10
A77: inicial | B77: Q2 | C77: perdas | D77: =AVERAGE(J12:J21) -> 94131.6 | E77: =MIN(J12:J21) -> 94005 | F77: =MAX(J12:J21) -> 94273 | G77: =COUNT(J12:J21) -> 10
A78: inicial | B78: Q2 | C78: perdas_h | D78: =AVERAGE(K12:K21) -> 4.0001992 | E78: =MIN(K12:K21) -> 3.9947542 | F78: =MAX(K12:K21) -> 4.0064575 | G78: =COUNT(K12:K21) -> 10
A79: inicial | B79: Q3 | C79: N | D79: =AVERAGE(E22:E31) -> 0.37507257 | E79: =MIN(E22:E31) -> 0.37473594 | F79: =MAX(E22:E31) -> 0.37532608 | G79: =COUNT(E22:E31) -> 10
A80: inicial | B80: Q3 | C80: B | D80: =AVERAGE(F22:F31) -> 0.37507257 | E80: =MIN(F22:F31) -> 0.37473594 | F80: =MAX(F22:F31) -> 0.37532608 | G80: =COUNT(F22:F31) -> 10
A81: inicial | B81: Q3 | C81: U | D81: =AVERAGE(G22:G31) -> 0.37507257 | E81: =MIN(G22:G31) -> 0.37473594 | F81: =MAX(G22:G31) -> 0.37532608 | G81: =COUNT(G22:G31) -> 10
A82: inicial | B82: Q3 | C82: D_h | D82: =AVERAGE(H22:H31) -> 7.5014514 | E82: =MIN(H22:H31) -> 7.4947188 | F82: =MAX(H22:H31) -> 7.5065216 | G82: =COUNT(H22:H31) -> 10
A83: inicial | B83: Q3 | C83: W | D83: =AVERAGE(I22:I31) -> 3 | E83: =MIN(I22:I31) -> 3 | F83: =MAX(I22:I31) -> 3 | G83: =COUNT(I22:I31) -> 10
A84: inicial | B84: Q3 | C84: perdas | D84: =AVERAGE(J22:J31) -> 0 | E84: =MIN(J22:J31) -> 0 | F84: =MAX(J22:J31) -> 0 | G84: =COUNT(J22:J31) -> 10
A85: inicial | B85: Q3 | C85: perdas_h | D85: =AVERAGE(K22:K31) -> 0 | E85: =MIN(K22:K31) -> 0 | F85: =MAX(K22:K31) -> 0 | G85: =COUNT(K22:K31) -> 10
A86: melhorado | B86: Q1 | C86: N | D86: =AVERAGE(E32:E41) -> 0.50018131 | E86: =MIN(E32:E41) -> 0.49991252 | F86: =MAX(E32:E41) -> 0.50059389 | G86: =COUNT(E32:E41) -> 10
A87: melhorado | B87: Q1 | C87: B | D87: =AVERAGE(F32:F41) -> 0.50018131 | E87: =MIN(F32:F41) -> 0.49991252 | F87: =MAX(F32:F41) -> 0.50059389 | G87: =COUNT(F32:F41) -> 10
A88: melhorado | B88: Q1 | C88: U | D88: =AVERAGE(G32:G41) -> 0.50018131 | E88: =MIN(G32:G41) -> 0.49991252 | F88: =MAX(G32:G41) -> 0.50059389 | G88: =COUNT(G32:G41) -> 10
...
